Workbook

Sheet README
A1: School Timetable Dataset - Greenwood Public School (fictional)
A2: Nursery to Class 12, Academic Year 2026-27. Built as realistic test data for a timetable website, with deliberate teacher and room problems.
A4: Quick facts (live formulas)
A5: Sections | B5: =COUNTA(Sections!A2:A56) -> 55
A6: Students | B6: =SUM(Sections!G2:G56) -> 1856
A7: Teachers on roll | B7: =COUNTA(Teachers!A2:A100) -> 99
A8: Teachers not active (on leave) | B8: =COUNTIF(Teachers!L2:L100,"<>Active") -> 1
A9: Subjects | B9: =COUNTA(Subjects!A2:A26) -> 25
A10: Rooms (incl. labs) | B10: =COUNTA(Rooms!A2:A68) -> 67
A11: Lesson requirement rows | B11: =COUNTA(Requirements!A2:A588) -> 587
A12: Total periods needed per week | B12: =SUM(Requirements!G2:G588) -> 2400
A13: Subject-groups with SHORTAGE | B13: =Demand_vs_Supply!B5 -> 9
A14: Subject-groups TIGHT | B14: =Demand_vs_Supply!B6 -> 6
A15: Subject-groups SURPLUS | B15: =Demand_vs_Supply!B8 -> 5
A17: Sheets
A18: Sheet | B18: What it contains
A19: School_Config | B19: Working days, periods per day, bell timings and standard teacher load limits per designation.
A20: Sections | B20: All 55 sections with class, stream, strength, home room and class teacher.
A21: Subjects | B21: 25 subjects with category, room type and who teaches them.
A22: Teachers | B22: 99 teachers: designation, primary and secondary subject, wings, availability, weekly and daily limits, status, class-teacher duty.
A23: Requirements | B23: One row per section per subject: periods per week, double periods, max per day, teacher group and room type. This is the main input for a timetable generator.
A24: Rooms | B24: Home classrooms plus labs, library, ground and activity rooms with capacity.
A25: Demand_vs_Supply | B25: Formula sheet comparing periods needed against teacher capacity for every subject and teacher group, with SHORTAGE / TIGHT / BALANCED / SURPLUS flags.
A26: Room_Check | B26: Formula sheet comparing mandatory-room lessons against room slot capacity.
A27: Known_Issues | B27: Every deliberate problem hidden in the data with numbers and what the website should do about it.
A29: How the tables link
A30: Sections.Class_Teacher_ID -> Teachers.Teacher_ID
A31: Sections.Home_Room_ID -> Rooms.Room_ID
A32: Requirements.Section_ID -> Sections.Section_ID
A33: Requirements.Subject_ID -> Subjects.Subject_ID
A34: Teachers.Primary_Subject / Secondary_Subject -> Subjects.Subject_ID
A35: Teachers.Class_Teacher_Of -> Sections.Section_ID
A36: Requirements.Teacher_Group = Teachers.Designation (which pool of teachers can take the lesson)
A38: Assumptions
A39: - | B39: Data sheets (Sections, Subjects, Teachers, Requirements, Rooms) hold plain values so they export cleanly to CSV or JSON. Only README facts, Demand_vs_Supply and Room_Check use formulas.
A40: - | B40: Every section's weekly requirements add up exactly to its weekly slots (30 for Pre-Primary, 42 for Class 1-5, 48 for Class 6-12).
A41: - | B41: Supply counts a teacher only under their Primary_Subject. Secondary_Subject is spare flexibility the app can use to fix shortages.
A42: - | B42: Max_Periods_Week and Max_Periods_Day are standard limits (see School_Config), lower for part-time and visiting staff. They are assumptions, not CBSE rules.
A43: - | B43: Value Education / Class Teacher Period is not counted in subject supply because the class teacher always takes it.
A44: - | B44: All names, the school and the numbers are made up. Today's date used for Status_Till reasoning: 24-Oct-2026.
...

Sheet School_Config
A1: School configuration - Greenwood Public School (fictional), Academic Year 2026-27
A3: 1. Weekly structure by wing
A4: Wing | B4: Classes | C4: Working_Days | D4: Days_Per_Week | E4: Periods_Per_Day | F4: Weekly_Slots | G4: Day_Ends
A5: Pre-Primary | B5: Nursery, LKG, UKG | C5: Mon-Fri | D5: 5 | E5: 6 | F5: =D5*E5 -> 30 | G5: 12:20
A6: Primary | B6: Class 1-5 | C6: Mon-Sat | D6: 6 | E6: 7 | F6: =D6*E6 -> 42 | G6: 13:30
A7: Middle | B7: Class 6-8 | C7: Mon-Sat | D7: 6 | E7: 8 | F7: =D7*E7 -> 48 | G7: 14:10
A8: Secondary | B8: Class 9-10 | C8: Mon-Sat | D8: 6 | E8: 8 | F8: =D8*E8 -> 48 | G8: 14:10
A9: Senior Secondary | B9: Class 11-12 | C9: Mon-Sat | D9: 6 | E9: 8 | F9: =D9*E9 -> 48 | G9: 14:10
A11: 2. Bell schedule (every period is 40 minutes)
A12: Slot | B12: Start | C12: End | D12: Used_By
A13: P1 | B13: 08:00 | C13: 08:40 | D13: All wings
A14: P2 | B14: 08:40 | C14: 09:20 | D14: All wings
A15: P3 | B15: 09:20 | C15: 10:00 | D15: All wings
A16: Short Break | B16: 10:00 | C16: 10:20 | D16: All wings
A17: P4 | B17: 10:20 | C17: 11:00 | D17: All wings
A18: P5 | B18: 11:00 | C18: 11:40 | D18: All wings
A19: P6 | B19: 11:40 | C19: 12:20 | D19: All wings (Pre-Primary leaves after P6)
A20: Lunch Break | B20: 12:20 | C20: 12:50 | D20: Class 1 and above
A21: P7 | B21: 12:50 | C21: 13:30 | D21: Class 1 and above
A22: P8 | B22: 13:30 | C22: 14:10 | D22: Class 6 and above
A24: 3. Teacher groups and standard load limits
A25: Designation | B25: Meaning | C25: Classes_Taught | D25: Max_Periods_Week | E25: Max_Periods_Day | F25: Usual_Days
A26: NTT | B26: Nursery Teacher (class teacher of a pre-primary section) | C26: Nursery-UKG | D26: 28 | E26: 6 | F26: Mon-Fri
A27: PRT | B27: Primary Teacher | C27: Class 1-5 | D27: 30 | E27: 6 | F27: Mon-Sat
A28: TGT | B28: Trained Graduate Teacher | C28: Class 6-10 (Computer: Class 1-10) | D28: 30 | E28: 6 | F28: Mon-Sat
A29: PGT | B29: Post Graduate Teacher | C29: Class 11-12 | D29: 26 | E29: 5 | F29: Mon-Sat
A30: Specialist | B30: Art, Music, Dance, Physical Education, Library | C30: Across wings | D30: 30 | E30: 6 | F30: Mon-Sat
A32: Max_Periods_Week counts subject periods only. The class-teacher period (Value Education / Circle Time) is extra and always taken by the section's own class teacher.

Sheet Sections
A1: Section_ID | B1: Class_Name | C1: Class_Order | D1: Section | E1: Wing | F1: Stream | G1: Strength | H1: Home_Room_ID | I1: Class_Teacher_ID | J1: Class_Teacher_Name | K1: Working_Days | L1: Periods_Per_Day | M1: Weekly_Slots
A2: NUR-A | B2: Nursery | C2: 1 | D2: A | E2: Pre-Primary | F2: General | G2: 20 | H2: A-101 | I2: T043 | J2: Ruchi Ghosh | K2: Mon-Fri | L2: 6 | M2: 30
A3: NUR-B | B3: Nursery | C3: 1 | D3: B | E3: Pre-Primary | F3: General | G3: 22 | H3: A-102 | I3: T054 | J3: Garima Tandon | K3: Mon-Fri | L3: 6 | M3: 30
A4: LKG-A | B4: LKG | C4: 2 | D4: A | E4: Pre-Primary | F4: General | G4: 24 | H4: A-103 | I4: T064 | J4: Jyoti Nair | K4: Mon-Fri | L4: 6 | M4: 30
A5: LKG-B | B5: LKG | C5: 2 | D5: B | E5: Pre-Primary | F5: General | G5: 24 | H5: A-104 | I5: T073 | J5: Harleen Pandey | K5: Mon-Fri | L5: 6 | M5: 30
A6: LKG-C | B6: LKG | C6: 2 | D6: C | E6: Pre-Primary | F6: General | G6: 25 | H6: A-105 | I6: T078 | J6: Garima Malhotra | K6: Mon-Fri | L6: 6 | M6: 30
A7: UKG-A | B7: UKG | C7: 3 | D7: A | E7: Pre-Primary | F7: General | G7: 26 | H7: A-106 | I7: T090 | J7: Tanvi Mukherjee | K7: Mon-Fri | L7: 6 | M7: 30
A8: UKG-B | B8: UKG | C8: 3 | D8: B | E8: Pre-Primary | F8: General | G8: 20 | H8: A-107 | I8: T095 | J8: Chitra Singh | K8: Mon-Fri | L8: 6 | M8: 30
A9: 1-A | B9: Class 1 | C9: 4 | D9: A | E9: Primary | F9: General | G9: 33 | H9: A-108 | I9: T038 | J9: Pooja Bisht | K9: Mon-Sat | L9: 7 | M9: 42
A10: 1-B | B10: Class 1 | C10: 4 | D10: B | E10: Primary | F10: General | G10: 38 | H10: A-201 | I10: T091 | J10: Shalini Mehta | K10: Mon-Sat | L10: 7 | M10: 42
A11: 1-C | B11: Class 1 | C11: 4 | D11: C | E11: Primary | F11: General | G11: 36 | H11: A-202 | I11: T037 | J11: Sunita Sharma | K11: Mon-Sat | L11: 7 | M11: 42
A12: 1-D | B12: Class 1 | C12: 4 | D12: D | E12: Primary | F12: General | G12: 38 | H12: A-203 | I12: T024 | J12: Geeta Pandey | K12: Mon-Sat | L12: 7 | M12: 42
A13: 2-A | B13: Class 2 | C13: 5 | D13: A | E13: Primary | F13: General | G13: 37 | H13: A-204 | I13: T029 | J13: Vinod Ghosh | K13: Mon-Sat | L13: 7 | M13: 42
... A56: 12-D | B56: Class 12 | C56: 15 | D56: D | E56: Senior Secondary | F56: Humanities | G56: 32 | H56: C-302 | I56: T023 | J56: Archana Anand | K56: Mon-Sat | L56: 8 | M56: 48

Sheet Subjects
A1: Subject_ID | B1: Subject_Name | C1: Category | D1: Taught_By | E1: Room_Type | F1: Room_Mandatory | G1: Classes_Offered | H1: Notes
A2: ENG | B2: English | C2: Language | D2: Subject Teacher | E2: Home Classroom | F2: N | G2: Nursery-12 | H2: Compulsory for all
A3: HIN | B3: Hindi | C3: Language | D3: Subject Teacher | E3: Home Classroom | F3: N | G3: Nursery-10 | H3: Not offered in 11-12
A4: SAN | B4: Sanskrit | C4: Language | D4: Subject Teacher | E4: Home Classroom | F4: N | G4: 6-8 | H4: Third language
A5: MAT | B5: Mathematics | C5: Core | D5: Subject Teacher | E5: Home Classroom | F5: N | G5: Nursery-12 | H5: In 11-12 only Science (PCM) and Commerce
A6: EVS | B6: Environmental Studies | C6: Core | D6: Subject Teacher | E6: Home Classroom | F6: N | G6: Nursery-2 | H6: Replaced by Science + Social Science from Class 3
A7: SCI | B7: Science | C7: Core | D7: Subject Teacher | E7: Home Classroom | F7: N | G7: 3-10 | H7: Class 9-10 has 1 lab double period
A8: SST | B8: Social Science | C8: Core | D8: Subject Teacher | E8: Home Classroom | F8: N | G8: 3-10
A9: CS | B9: Computer Science / IT | C9: Skill | D9: Subject Teacher | E9: Computer Lab | F9: Y | G9: 1-10, 11-12 (PCM) | H9: All periods are held in a Computer Lab
A10: PHY | B10: Physics | C10: Senior Science | D10: Subject Teacher | E10: Physics Lab | F10: Y | G10: 11-12 Science | H10: 1 double (practical) period per week
A11: CHE | B11: Chemistry | C11: Senior Science | D11: Subject Teacher | E11: Chemistry Lab | F11: Y | G11: 11-12 Science | H11: 1 double (practical) period per week
A12: BIO | B12: Biology | C12: Senior Science | D12: Subject Teacher | E12: Biology Lab | F12: Y | G12: 11-12 PCB | H12: 1 double (practical) period per week
A13: PSY | B13: Psychology | C13: Elective | D13: Subject Teacher | E13: Home Classroom | F13: N | G13: 11-12 PCB
A14: ACC | B14: Accountancy | C14: Elective | D14: Subject Teacher | E14: Home Classroom | F14: N | G14: 11-12 Commerce
A15: BST | B15: Business Studies | C15: Elective | D15: Subject Teacher | E15: Home Classroom | F15: N | G15: 11-12 Commerce
A16: ECO | B16: Economics | C16: Elective | D16: Subject Teacher | E16: Home Classroom | F16: N | G16: 11-12 Commerce, Humanities | H16: Shared between two streams
A17: HIS | B17: History | C17: Elective | D17: Subject Teacher | E17: Home Classroom | F17: N | G17: 11-12 Humanities
A18: POL | B18: Political Science | C18: Elective | D18: Subject Teacher | E18: Home Classroom | F18: N | G18: 11-12 Humanities
A19: GEO | B19: Geography | C19: Elective | D19: Subject Teacher | E19: Home Classroom | F19: N | G19: 11-12 Humanities
A20: ART | B20: Art & Craft | C20: Co-scholastic | D20: Specialist | E20: Art Room | F20: N | G20: Nursery-10 | H20: Art Room preferred, can run in home room
A21: MUS | B21: Music | C21: Co-scholastic | D21: Specialist | E21: Music Room | F21: N | G21: Nursery-8 | H21: Music Room preferred, can run in home room
A22: DAN | B22: Dance | C22: Co-scholastic | D22: Specialist | E22: Dance Studio | F22: Y | G22: 1-8 | H22: Pre-primary dance is part of Music
A23: PE | B23: Physical Education | C23: Co-scholastic | D23: Specialist | E23: Playground | F23: Y | G23: Nursery-12 | H23: Nursery-UKG use the Play Area instead of the Playground
A24: LIB | B24: Library & Reading | C24: Co-scholastic | D24: Specialist | E24: Library | F24: Y | G24: 1-12
A25: RHY | B25: Rhymes & Storytelling | C25: Pre-Primary | D25: Subject Teacher | E25: Home Classroom | F25: N | G25: Nursery-UKG
A26: VE | B26: Value Education / Class Teacher Period | C26: Co-scholastic | D26: Class Teacher | E26: Home Classroom | F26: N | G26: Nursery-12 | H26: Always taken by the section's own class teacher (not counted in subject supply)

Sheet Teachers
A1: Teacher_ID | B1: Teacher_Name | C1: Gender | D1: Designation | E1: Primary_Subject | F1: Secondary_Subject | G1: Teaching_Wings | H1: Employment_Type | I1: Max_Periods_Week | J1: Max_Periods_Day | K1: Working_Days | L1: Status | M1: Status_Till | N1: Class_Teacher_Of | O1: Qualification | P1: Joining_Year | Q1: Remarks
A2: T001 | B2: Nidhi Tiwari | C2: F | D2: PGT | E2: PHY | G2: Senior Secondary | H2: Full-time | I2: 26 | J2: 5 | K2: Mon-Sat | L2: Active | O2: M.Sc. (Physics), B.Ed. | P2: 2003 | Q2: Only Physics PGT in the school.
A3: T002 | B3: Madhu Sinha | C3: F | D3: PGT | E3: MAT | G3: Senior Secondary | H3: Full-time | I3: 26 | J3: 5 | K3: Mon-Sat | L3: On Leave | M3: 46418 | N3: 11-C | O3: M.Sc. (Maths), B.Ed. | P3: 2004 | Q3: On maternity leave until 31-Jan-2027. Class teacher of 11-C (needs a substitute).
A4: T003 | B4: Archana Kapoor | C4: F | D4: PGT | E4: GEO | G4: Senior Secondary | H4: Full-time | I4: 26 | J4: 5 | K4: Mon-Sat | L4: Active | O4: M.A. (Geography), B.Ed. | P4: 2006
A5: T004 | B5: Pradeep Malhotra | C5: M | D5: PGT | E5: ACC | F5: ECO | G5: Senior Secondary | H5: Full-time | I5: 26 | J5: 5 | K5: Mon-Sat | L5: Active | N5: 11-D | O5: M.Com, B.Ed. | P5: 2007 | Q5: Only Accountancy PGT.
A6: T005 | B6: Madhu Mehta | C6: F | D6: TGT | E6: CS | F6: MAT | G6: Primary;Middle;Secondary | H6: Full-time | I6: 30 | J6: 6 | K6: Mon-Sat | L6: Active | O6: M.Sc. (IT), B.Ed. | P6: 2007
A7: T006 | B7: Rajesh Chopra | C7: M | D7: PGT | E7: HIS | F7: POL | G7: Senior Secondary | H7: Full-time | I7: 26 | J7: 5 | K7: Mon-Sat | L7: Active | N7: 11-F | O7: M.A. (History), B.Ed. | P7: 2007
A8: T007 | B8: Umesh Chopra | C8: M | D8: Specialist | E8: PE | G8: All | H8: Full-time | I8: 30 | J8: 6 | K8: Mon-Sat | L8: Active | O8: M.P.Ed. | P8: 2008 | Q8: Head of Sports Department
A9: T008 | B9: Aarti Banerjee | C9: F | D9: TGT | E9: SST | G9: Middle;Secondary | H9: Full-time | I9: 30 | J9: 6 | K9: Mon-Sat | L9: Active | N9: 6-A | O9: M.A. (Pol. Sc.), B.Ed. | P9: 2008
A10: T009 | B10: Radha Bansal | C10: F | D10: TGT | E10: HIN | F10: SAN | G10: Middle;Secondary | H10: Full-time | I10: 30 | J10: 6 | K10: Mon-Sat | L10: Active | N10: 6-C | O10: M.A. (Hindi), B.Ed. | P10: 2009
A11: T010 | B11: Sunita Mehta | C11: F | D11: TGT | E11: ENG | G11: Middle;Secondary | H11: Full-time | I11: 30 | J11: 6 | K11: Mon-Sat | L11: Active | N11: 9-C | O11: M.A. (English), B.Ed. | P11: 2009
A12: T011 | B12: Tarun Khanna | C12: M | D12: TGT | E12: SAN | F12: HIN | G12: Middle;Secondary | H12: Full-time | I12: 30 | J12: 6 | K12: Mon-Sat | L12: Active | O12: M.A. (Sanskrit), B.Ed. | P12: 2010 | Q12: Only Sanskrit teacher in the school.
A13: T012 | B13: Lata Pandey | C13: F | D13: TGT | E13: CS | G13: Primary;Middle;Secondary | H13: Full-time | I13: 30 | J13: 6 | K13: Mon-Sat | L13: Active | O13: MCA, B.Ed. | P13: 2010
A14: T013 | B14: Amit Dubey | C14: M | D14: PGT | E14: CHE | G14: Senior Secondary | H14: Full-time | I14: 26 | J14: 5 | K14: Mon-Sat | L14: Active | N14: 11-A | O14: M.Sc. (Chemistry), B.Ed. | P14: 2010
A15: T014 | B15: Preeti Tandon | C15: F | D15: PRT | E15: SST | F15: HIN | G15: Primary | H15: Full-time | I15: 30 | J15: 6 | K15: Mon-Sat | L15: Active | O15: B.A., B.Ed. | P15: 2010
A16: T015 | B16: Vivek Sharma | C16: M | D16: TGT | E16: HIN | G16: Middle;Secondary | H16: Full-time | I16: 30 | J16: 6 | K16: Mon-Sat | L16: Active | N16: 7-C | O16: M.A. (Hindi), B.Ed. | P16: 2010
A17: T016 | B17: Manju Mukherjee | C17: F | D17: Specialist | E17: PE | G17: All | H17: Full-time | I17: 30 | J17: 6 | K17: Mon-Sat | L17: Active | O17: M.P.Ed. | P17: 2010
A18: T017 | B18: Kavita Malhotra | C18: F | D18: PGT | E18: PSY | G18: Senior Secondary | H18: Part-time | I18: 15 | J18: 5 | K18: Mon,Wed,Fri | L18: Active | O18: M.A. (Psychology), M.Phil. | P18: 2010 | Q18: Part-time psychology teacher / counsellor. Only Mon, Wed, Fri.
A19: T018 | B19: Aarti Walia | C19: F | D19: TGT | E19: SST | F19: ENG | G19: Middle;Secondary | H19: Full-time | I19: 30 | J19: 6 | K19: Mon-Sat | L19: Active | N19: 7-A | O19: M.A. (Pol. Sc.), B.Ed. | P19: 2010
A20: T019 | B20: Rohit Jain | C20: M | D20: PGT | E20: BST | G20: Senior Secondary | H20: Full-time | I20: 26 | J20: 5 | K20: Mon-Sat | L20: Active | N20: 12-C | O20: M.Com, B.Ed. | P20: 2011 | Q20: Only Business Studies PGT.
A21: T020 | B21: Pradeep Kumar | C21: M | D21: Specialist | E21: PE | G21: All | H21: Full-time | I21: 30 | J21: 6 | K21: Mon-Sat | L21: Active | O21: B.P.Ed. | P21: 2011
A22: T021 | B22: Gopal Joshi | C22: M | D22: TGT | E22: ENG | G22: Middle;Secondary | H22: Full-time | I22: 30 | J22: 6 | K22: Mon-Sat | L22: Active | N22: 10-B | O22: M.A. (English), B.Ed. | P22: 2011
A23: T022 | B23: Renu Banerjee | C23: F | D23: TGT | E23: CS | G23: Primary;Middle;Secondary | H23: Part-time | I23: 15 | J23: 5 | K23: Mon,Wed,Fri | L23: Active | O23: M.Sc. (IT), B.Ed. | P23: 2011 | Q23: Part-time computer teacher; available Mon, Wed, Fri only.
A24: T023 | B24: Archana Anand | C24: F | D24: PGT | E24: POL | F24: HIS | G24: Senior Secondary | H24: Full-time | I24: 26 | J24: 5 | K24: Mon-Sat | L24: Active | N24: 12-D | O24: M.A. (Pol. Sc.), B.Ed. | P24: 2012
A25: T024 | B25: Geeta Pandey | C25: F | D25: PRT | E25: MAT | G25: Primary | H25: Full-time | I25: 30 | J25: 6 | K25: Mon-Sat | L25: Active | N25: 1-D | O25: B.Sc. (Maths), B.Ed. | P25: 2012
A26: T025 | B26: Bhavna Gill | C26: F | D26: TGT | E26: MAT | F26: CS | G26: Middle;Secondary | H26: Full-time | I26: 30 | J26: 6 | K26: Mon-Sat | L26: Active | N26: 9-A | O26: M.Sc. (Maths), B.Ed. | P26: 2012
A27: T026 | B27: Rahul Mishra | C27: M | D27: Specialist | E27: PE | G27: All | H27: Full-time | I27: 30 | J27: 6 | K27: Mon-Sat | L27: Active | O27: B.P.Ed. | P27: 2012
A28: T027 | B28: Hemant Singh | C28: M | D28: TGT | E28: ENG | G28: Middle;Secondary | H28: Full-time | I28: 30 | J28: 6 | K28: Mon-Sat | L28: Active | N28: 9-D | O28: M.A. (English), B.Ed. | P28: 2012
A29: T028 | B29: Poonam Thakur | C29: F | D29: TGT | E29: HIN | F29: SAN | G29: Middle;Secondary | H29: Full-time | I29: 30 | J29: 6 | K29: Mon-Sat | L29: Active | N29: 10-A | O29: M.A. (Hindi), B.Ed. | P29: 2012
A30: T029 | B30: Vinod Ghosh | C30: M | D30: PRT | E30: MAT | F30: CS | G30: Primary | H30: Full-time | I30: 30 | J30: 6 | K30: Mon-Sat | L30: Active | N30: 2-A | O30: B.Sc. (Maths), B.Ed. | P30: 2012
A31: T030 | B31: Rajesh Kumar | C31: M | D31: TGT | E31: MAT | F31: CS | G31: Middle;Secondary | H31: Full-time | I31: 30 | J31: 6 | K31: Mon-Sat | L31: Active | N31: 6-D | O31: M.Sc. (Maths), B.Ed. | P31: 2012
A32: T031 | B32: Tanvi Gill | C32: F | D32: TGT | E32: ENG | F32: SST | G32: Middle;Secondary | H32: Full-time | I32: 30 | J32: 6 | K32: Mon-Sat | L32: Active | N32: 8-A | O32: M.A. (English), B.Ed. | P32: 2013
A33: T032 | B33: Rajesh Sinha | C33: M | D33: PGT | E33: BIO | G33: Senior Secondary | H33: Full-time | I33: 26 | J33: 5 | K33: Mon-Sat | L33: Active | N33: 11-B | O33: M.Sc. (Zoology), B.Ed. | P33: 2013 | Q33: Only Biology PGT in the school.
A34: T033 | B34: Sapna Bedi | C34: F | D34: PRT | E34: HIN | F34: ENG | G34: Primary | H34: Full-time | I34: 30 | J34: 6 | K34: Mon-Sat | L34: Active | N34: 2-B | O34: M.A. (Hindi), B.Ed. | P34: 2013
A35: T034 | B35: Suresh Chauhan | C35: M | D35: Specialist | E35: ART | G35: Pre-Primary;Primary;Middle;Secondary | H35: Full-time | I35: 30 | J35: 6 | K35: Mon-Sat | L35: Active | O35: BFA, B.Ed. | P35: 2013
A36: T035 | B36: Rachna Tandon | C36: F | D36: PRT | E36: ENG | G36: Primary | H36: Full-time | I36: 30 | J36: 6 | K36: Mon-Sat | L36: Active | N36: 5-D | O36: M.A. (English), B.Ed. | P36: 2013
A37: T036 | B37: Rakesh Rawat | C37: M | D37: PGT | E37: ENG | G37: Senior Secondary | H37: Full-time | I37: 26 | J37: 5 | K37: Mon-Sat | L37: Active | N37: 12-A | O37: M.A. (English), B.Ed. | P37: 2014
A38: T037 | B38: Sunita Sharma | C38: F | D38: PRT | E38: ENG | F38: HIN | G38: Primary | H38: Full-time | I38: 30 | J38: 6 | K38: Mon-Sat | L38: Active | N38: 1-C | O38: M.A. (English), B.Ed. | P38: 2014
A39: T038 | B39: Pooja Bisht | C39: F | D39: PRT | E39: EVS | F39: SST | G39: Primary | H39: Full-time | I39: 30 | J39: 6 | K39: Mon-Sat | L39: Active | N39: 1-A | O39: B.A., D.El.Ed. | P39: 2014
A40: T039 | B40: Divya Sharma | C40: F | D40: PRT | E40: SCI | F40: EVS | G40: Primary | H40: Full-time | I40: 30 | J40: 6 | K40: Mon-Sat | L40: Active | N40: 5-A | O40: B.Sc., B.Ed. | P40: 2014
...

Sheet Requirements
A1: Req_ID | B1: Section_ID | C1: Class_Name | D1: Wing | E1: Subject_ID | F1: Subject_Name | G1: Periods_Per_Week | H1: Double_Periods | I1: Max_Per_Day | J1: Teacher_Group | K1: Room_Type | L1: Room_Mandatory
A2: R0001 | B2: NUR-A | C2: Nursery | D2: Pre-Primary | E2: ENG | F2: English | G2: 6 | H2: 0 | I2: 2 | J2: NTT | K2: Home Classroom | L2: N
A3: R0002 | B3: NUR-A | C3: Nursery | D3: Pre-Primary | E3: HIN | F3: Hindi | G3: 4 | H3: 0 | I3: 1 | J3: NTT | K3: Home Classroom | L3: N
A4: R0003 | B4: NUR-A | C4: Nursery | D4: Pre-Primary | E4: MAT | F4: Mathematics | G4: 5 | H4: 0 | I4: 1 | J4: NTT | K4: Home Classroom | L4: N
A5: R0004 | B5: NUR-A | C5: Nursery | D5: Pre-Primary | E5: EVS | F5: Environmental Studies | G5: 3 | H5: 0 | I5: 1 | J5: NTT | K5: Home Classroom | L5: N
A6: R0005 | B6: NUR-A | C6: Nursery | D6: Pre-Primary | E6: RHY | F6: Rhymes & Storytelling | G6: 3 | H6: 0 | I6: 1 | J6: NTT | K6: Home Classroom | L6: N
A7: R0006 | B7: NUR-A | C7: Nursery | D7: Pre-Primary | E7: ART | F7: Art & Craft | G7: 3 | H7: 0 | I7: 1 | J7: Specialist | K7: Art Room | L7: N
A8: R0007 | B8: NUR-A | C8: Nursery | D8: Pre-Primary | E8: MUS | F8: Music | G8: 2 | H8: 0 | I8: 1 | J8: Specialist | K8: Music Room | L8: N
A9: R0008 | B9: NUR-A | C9: Nursery | D9: Pre-Primary | E9: PE | F9: Physical Education | G9: 3 | H9: 0 | I9: 1 | J9: Specialist | K9: Play Area | L9: Y
A10: R0009 | B10: NUR-A | C10: Nursery | D10: Pre-Primary | E10: VE | F10: Value Education / Class Teacher Period | G10: 1 | H10: 0 | I10: 1 | J10: Class Teacher | K10: Home Classroom | L10: N
A11: R0010 | B11: NUR-B | C11: Nursery | D11: Pre-Primary | E11: ENG | F11: English | G11: 6 | H11: 0 | I11: 2 | J11: NTT | K11: Home Classroom | L11: N
A12: R0011 | B12: NUR-B | C12: Nursery | D12: Pre-Primary | E12: HIN | F12: Hindi | G12: 4 | H12: 0 | I12: 1 | J12: NTT | K12: Home Classroom | L12: N
A13: R0012 | B13: NUR-B | C13: Nursery | D13: Pre-Primary | E13: MAT | F13: Mathematics | G13: 5 | H13: 0 | I13: 1 | J13: NTT | K13: Home Classroom | L13: N
... A588: R0587 | B588: 12-D | C588: Class 12 | D588: Senior Secondary | E588: VE | F588: Value Education / Class Teacher Period | G588: 1 | H588: 0 | I588: 1 | J588: Class Teacher | K588: Home Classroom | L588: N

Sheet Rooms
A1: Room_ID | B1: Room_Name | C1: Block | D1: Floor | E1: Room_Type | F1: Capacity_Students | G1: Parallel_Classes | H1: Assigned_Section
A2: A-101 | B2: Classroom A-101 | C2: A | D2: 1 | E2: Home Classroom | F2: 28 | G2: 1 | H2: NUR-A
A3: A-102 | B3: Classroom A-102 | C3: A | D3: 1 | E3: Home Classroom | F3: 28 | G3: 1 | H3: NUR-B
A4: A-103 | B4: Classroom A-103 | C4: A | D4: 1 | E4: Home Classroom | F4: 28 | G4: 1 | H4: LKG-A
A5: A-104 | B5: Classroom A-104 | C5: A | D5: 1 | E5: Home Classroom | F5: 28 | G5: 1 | H5: LKG-B
A6: A-105 | B6: Classroom A-105 | C6: A | D6: 1 | E6: Home Classroom | F6: 28 | G6: 1 | H6: LKG-C
A7: A-106 | B7: Classroom A-106 | C7: A | D7: 1 | E7: Home Classroom | F7: 28 | G7: 1 | H7: UKG-A
A8: A-107 | B8: Classroom A-107 | C8: A | D8: 1 | E8: Home Classroom | F8: 28 | G8: 1 | H8: UKG-B
A9: A-108 | B9: Classroom A-108 | C9: A | D9: 1 | E9: Home Classroom | F9: 40 | G9: 1 | H9: 1-A
A10: A-201 | B10: Classroom A-201 | C10: A | D10: 2 | E10: Home Classroom | F10: 40 | G10: 1 | H10: 1-B
A11: A-202 | B11: Classroom A-202 | C11: A | D11: 2 | E11: Home Classroom | F11: 40 | G11: 1 | H11: 1-C
A12: A-203 | B12: Classroom A-203 | C12: A | D12: 2 | E12: Home Classroom | F12: 40 | G12: 1 | H12: 1-D
A13: A-204 | B13: Classroom A-204 | C13: A | D13: 2 | E13: Home Classroom | F13: 40 | G13: 1 | H13: 2-A
... A56: C-302 | B56: Classroom C-302 | C56: C | D56: 3 | E56: Home Classroom | F56: 45 | G56: 1 | H56: 12-D
A57: CL-1 | B57: Computer Lab 1 | C57: B | D57: 1 | E57: Computer Lab | F57: 40 | G57: 1
A58: CL-2 | B58: Computer Lab 2 | C58: B | D58: 1 | E58: Computer Lab | F58: 40 | G58: 1
A59: PL-1 | B59: Physics Lab | C59: C | D59: 1 | E59: Physics Lab | F59: 40 | G59: 1
A60: CH-1 | B60: Chemistry Lab | C60: C | D60: 1 | E60: Chemistry Lab | F60: 40 | G60: 1
A61: BL-1 | B61: Biology Lab | C61: C | D61: 1 | E61: Biology Lab | F61: 40 | G61: 1
A62: LIB-1 | B62: Library | C62: A | D62: 1 | E62: Library | F62: 80 | G62: 2
A63: PG-1 | B63: Sports Ground | C63: - | D63: 0 | E63: Playground | F63: 160 | G63: 4
A64: PA-1 | B64: Pre-Primary Play Area | C64: A | D64: 0 | E64: Play Area | F64: 60 | G64: 2
A65: AR-1 | B65: Art Room 1 | C65: B | D65: 2 | E65: Art Room | F65: 40 | G65: 1
A66: AR-2 | B66: Art Room 2 | C66: B | D66: 2 | E66: Art Room | F66: 40 | G66: 1
A67: MR-1 | B67: Music Room | C67: A | D67: 2 | E67: Music Room | F67: 40 | G67: 1
A68: DS-1 | B68: Dance Studio | C68: A | D68: 2 | E68: Dance Studio | F68: 45 | G68: 1

Sheet Demand_vs_Supply
A1: Teacher demand vs supply (live formulas)
A2: Demand = periods per week all sections need (Requirements). Supply = Max_Periods_Week of teachers whose Primary_Subject and Designation match. Effective capacity counts only teachers with Status = Active.
A4: Status | B4: Count | D4: Thresholds (edit to taste)
A5: SHORTAGE | B5: =COUNTIF($M$13:$M$48,A5) -> 9 | D5: TIGHT when utilization >= | E5: 0.9
A6: TIGHT | B6: =COUNTIF($M$13:$M$48,A6) -> 6 | D6: BALANCED when utilization >= | E6: 0.6
A7: BALANCED | B7: =COUNTIF($M$13:$M$48,A7) -> 16 | D7: Below the BALANCED line = SURPLUS; above 100% = SHORTAGE.
A8: SURPLUS | B8: =COUNTIF($M$13:$M$48,A8) -> 5
A9: NO TEACHER | B9: =COUNTIF($M$13:$M$48,A9) -> 0
A12: Subject_ID | B12: Subject | C12: Teacher_Group | D12: Classes_Covered | E12: Periods_Needed_Week | F12: Teachers_On_Roll | G12: Teachers_Active | H12: Nominal_Capacity | I12: Effective_Capacity | J12: Gap (Capacity - Need) | K12: Utilization | L12: Teachers_Short(-)/Spare(+) | M12: Status
A13: ENG | B13: English | C13: NTT | D13: Nursery-UKG | E13: =SUMIFS(Requirements!$G$2:$G$588,Requirements!$E$2:$E$588,$A13,Requirements!$J$2:$J$588,$C13) -> 42 | F13: =COUNTIFS(Teachers!$E$2:$E$100,$A13,Teachers!$D$2:$D$100,$C13) -> 2 | G13: =COUNTIFS(Teachers!$E$2:$E$100,$A13,Teachers!$D$2:$D$100,$C13,Teachers!$L$2:$L$100,"Active") -> 2 | H13: =SUMIFS(Teachers!$I$2:$I$100,Teachers!$E$2:$E$100,$A13,Teachers!$D$2:$D$100,$C13) -> 56 | I13: =SUMIFS(Teachers!$I$2:$I$100,Teachers!$E$2:$E$100,$A13,Teachers!$D$2:$D$100,$C13,Teachers!$L$2:$L$100,"Active") -> 56 | J13: =I13-E13 -> 14 | K13: =IF(I13=0,"n/a",E13/I13) -> 0.75 | L13: =IF(G13=0,"n/a",ROUND(J13/(I13/G13),1)) -> 0.5 | M13: =IF(I13=0,"NO TEACHER",IF(E13/I13>1,"SHORTAGE",IF(E13/I13>=$E$5,"TIGHT",IF(E13/I13>=$E$6,"BALANCED","SURPLUS")))) -> BALANCED
A14: HIN | B14: Hindi | C14: NTT | D14: Nursery-UKG | E14: =SUMIFS(Requirements!$G$2:$G$588,Requirements!$E$2:$E$588,$A14,Requirements!$J$2:$J$588,$C14) -> 28 | F14: =COUNTIFS(Teachers!$E$2:$E$100,$A14,Teachers!$D$2:$D$100,$C14) -> 1 | G14: =COUNTIFS(Teachers!$E$2:$E$100,$A14,Teachers!$D$2:$D$100,$C14,Teachers!$L$2:$L$100,"Active") -> 1 | H14: =SUMIFS(Teachers!$I$2:$I$100,Teachers!$E$2:$E$100,$A14,Teachers!$D$2:$D$100,$C14) -> 28 | I14: =SUMIFS(Teachers!$I$2:$I$100,Teachers!$E$2:$E$100,$A14,Teachers!$D$2:$D$100,$C14,Teachers!$L$2:$L$100,"Active") -> 28 | J14: =I14-E14 -> 0 | K14: =IF(I14=0,"n/a",E14/I14) -> 1 | L14: =IF(G14=0,"n/a",ROUND(J14/(I14/G14),1)) -> 0 | M14: =IF(I14=0,"NO TEACHER",IF(E14/I14>1,"SHORTAGE",IF(E14/I14>=$E$5,"TIGHT",IF(E14/I14>=$E$6,"BALANCED","SURPLUS")))) -> TIGHT
A15: MAT | B15: Mathematics | C15: NTT | D15: Nursery-UKG | E15: =SUMIFS(Requirements!$G$2:$G$588,Requirements!$E$2:$E$588,$A15,Requirements!$J$2:$J$588,$C15) -> 35 | F15: =COUNTIFS(Teachers!$E$2:$E$100,$A15,Teachers!$D$2:$D$100,$C15) -> 2 | G15: =COUNTIFS(Teachers!$E$2:$E$100,$A15,Teachers!$D$2:$D$100,$C15,Teachers!$L$2:$L$100,"Active") -> 2 | H15: =SUMIFS(Teachers!$I$2:$I$100,Teachers!$E$2:$E$100,$A15,Teachers!$D$2:$D$100,$C15) -> 56 | I15: =SUMIFS(Teachers!$I$2:$I$100,Teachers!$E$2:$E$100,$A15,Teachers!$D$2:$D$100,$C15,Teachers!$L$2:$L$100,"Active") -> 56 | J15: =I15-E15 -> 21 | K15: =IF(I15=0,"n/a",E15/I15) -> 0.625 | L15: =IF(G15=0,"n/a",ROUND(J15/(I15/G15),1)) -> 0.8 | M15: =IF(I15=0,"NO TEACHER",IF(E15/I15>1,"SHORTAGE",IF(E15/I15>=$E$5,"TIGHT",IF(E15/I15>=$E$6,"BALANCED","SURPLUS")))) -> BALANCED
A16: EVS | B16: Environmental Studies | C16: NTT | D16: Nursery-UKG | E16: =SUMIFS(Requirements!$G$2:$G$588,Requirements!$E$2:$E$588,$A16,Requirements!$J$2:$J$588,$C16) -> 21 | F16: =COUNTIFS(Teachers!$E$2:$E$100,$A16,Teachers!$D$2:$D$100,$C16) -> 1 | G16: =COUNTIFS(Teachers!$E$2:$E$100,$A16,Teachers!$D$2:$D$100,$C16,Teachers!$L$2:$L$100,"Active") -> 1 | H16: =SUMIFS(Teachers!$I$2:$I$100,Teachers!$E$2:$E$100,$A16,Teachers!$D$2:$D$100,$C16) -> 28 | I16: =SUMIFS(Teachers!$I$2:$I$100,Teachers!$E$2:$E$100,$A16,Teachers!$D$2:$D$100,$C16,Teachers!$L$2:$L$100,"Active") -> 28 | J16: =I16-E16 -> 7 | K16: =IF(I16=0,"n/a",E16/I16) -> 0.75 | L16: =IF(G16=0,"n/a",ROUND(J16/(I16/G16),1)) -> 0.3 | M16: =IF(I16=0,"NO TEACHER",IF(E16/I16>1,"SHORTAGE",IF(E16/I16>=$E$5,"TIGHT",IF(E16/I16>=$E$6,"BALANCED","SURPLUS")))) -> BALANCED
A17: RHY | B17: Rhymes & Storytelling | C17: NTT | D17: Nursery-UKG | E17: =SUMIFS(Requirements!$G$2:$G$588,Requirements!$E$2:$E$588,$A17,Requirements!$J$2:$J$588,$C17) -> 21 | F17: =COUNTIFS(Teachers!$E$2:$E$100,$A17,Teachers!$D$2:$D$100,$C17) -> 1 | G17: =COUNTIFS(Teachers!$E$2:$E$100,$A17,Teachers!$D$2:$D$100,$C17,Teachers!$L$2:$L$100,"Active") -> 1 | H17: =SUMIFS(Teachers!$I$2:$I$100,Teachers!$E$2:$E$100,$A17,Teachers!$D$2:$D$100,$C17) -> 28 | I17: =SUMIFS(Teachers!$I$2:$I$100,Teachers!$E$2:$E$100,$A17,Teachers!$D$2:$D$100,$C17,Teachers!$L$2:$L$100,"Active") -> 28 | J17: =I17-E17 -> 7 | K17: =IF(I17=0,"n/a",E17/I17) -> 0.75 | L17: =IF(G17=0,"n/a",ROUND(J17/(I17/G17),1)) -> 0.3 | M17: =IF(I17=0,"NO TEACHER",IF(E17/I17>1,"SHORTAGE",IF(E17/I17>=$E$5,"TIGHT",IF(E17/I17>=$E$6,"BALANCED","SURPLUS")))) -> BALANCED
A18: ENG | B18: English | C18: PRT | D18: Class 1-5 | E18: =SUMIFS(Requirements!$G$2:$G$588,Requirements!$E$2:$E$588,$A18,Requirements!$J$2:$J$588,$C18) -> 152 | F18: =COUNTIFS(Teachers!$E$2:$E$100,$A18,Teachers!$D$2:$D$100,$C18) -> 6 | G18: =COUNTIFS(Teachers!$E$2:$E$100,$A18,Teachers!$D$2:$D$100,$C18,Teachers!$L$2:$L$100,"Active") -> 6 | H18: =SUMIFS(Teachers!$I$2:$I$100,Teachers!$E$2:$E$100,$A18,Teachers!$D$2:$D$100,$C18) -> 180 | I18: =SUMIFS(Teachers!$I$2:$I$100,Teachers!$E$2:$E$100,$A18,Teachers!$D$2:$D$100,$C18,Teachers!$L$2:$L$100,"Active") -> 180 | J18: =I18-E18 -> 28 | K18: =IF(I18=0,"n/a",E18/I18) -> 0.84444444 | L18: =IF(G18=0,"n/a",ROUND(J18/(I18/G18),1)) -> 0.9 | M18: =IF(I18=0,"NO TEACHER",IF(E18/I18>1,"SHORTAGE",IF(E18/I18>=$E$5,"TIGHT",IF(E18/I18>=$E$6,"BALANCED","SURPLUS")))) -> BALANCED
A19: HIN | B19: Hindi | C19: PRT | D19: Class 1-5 | E19: =SUMIFS(Requirements!$G$2:$G$588,Requirements!$E$2:$E$588,$A19,Requirements!$J$2:$J$588,$C19) -> 114 | F19: =COUNTIFS(Teachers!$E$2:$E$100,$A19,Teachers!$D$2:$D$100,$C19) -> 4 | G19: =COUNTIFS(Teachers!$E$2:$E$100,$A19,Teachers!$D$2:$D$100,$C19,Teachers!$L$2:$L$100,"Active") -> 4 | H19: =SUMIFS(Teachers!$I$2:$I$100,Teachers!$E$2:$E$100,$A19,Teachers!$D$2:$D$100,$C19) -> 120 | I19: =SUMIFS(Teachers!$I$2:$I$100,Teachers!$E$2:$E$100,$A19,Teachers!$D$2:$D$100,$C19,Teachers!$L$2:$L$100,"Active") -> 120 | J19: =I19-E19 -> 6 | K19: =IF(I19=0,"n/a",E19/I19) -> 0.95 | L19: =IF(G19=0,"n/a",ROUND(J19/(I19/G19),1)) -> 0.2 | M19: =IF(I19=0,"NO TEACHER",IF(E19/I19>1,"SHORTAGE",IF(E19/I19>=$E$5,"TIGHT",IF(E19/I19>=$E$6,"BALANCED","SURPLUS")))) -> TIGHT
A20: MAT | B20: Mathematics | C20: PRT | D20: Class 1-5 | E20: =SUMIFS(Requirements!$G$2:$G$588,Requirements!$E$2:$E$588,$A20,Requirements!$J$2:$J$588,$C20) -> 145 | F20: =COUNTIFS(Teachers!$E$2:$E$100,$A20,Teachers!$D$2:$D$100,$C20) -> 5 | G20: =COUNTIFS(Teachers!$E$2:$E$100,$A20,Teachers!$D$2:$D$100,$C20,Teachers!$L$2:$L$100,"Active") -> 5 | H20: =SUMIFS(Teachers!$I$2:$I$100,Teachers!$E$2:$E$100,$A20,Teachers!$D$2:$D$100,$C20) -> 150 | I20: =SUMIFS(Teachers!$I$2:$I$100,Teachers!$E$2:$E$100,$A20,Teachers!$D$2:$D$100,$C20,Teachers!$L$2:$L$100,"Active") -> 150 | J20: =I20-E20 -> 5 | K20: =IF(I20=0,"n/a",E20/I20) -> 0.96666667 | L20: =IF(G20=0,"n/a",ROUND(J20/(I20/G20),1)) -> 0.2 | M20: =IF(I20=0,"NO TEACHER",IF(E20/I20>1,"SHORTAGE",IF(E20/I20>=$E$5,"TIGHT",IF(E20/I20>=$E$6,"BALANCED","SURPLUS")))) -> TIGHT
A21: EVS | B21: Environmental Studies | C21: PRT | D21: Class 1-5 | E21: =SUMIFS(Requirements!$G$2:$G$588,Requirements!$E$2:$E$588,$A21,Requirements!$J$2:$J$588,$C21) -> 35 | F21: =COUNTIFS(Teachers!$E$2:$E$100,$A21,Teachers!$D$2:$D$100,$C21) -> 3 | G21: =COUNTIFS(Teachers!$E$2:$E$100,$A21,Teachers!$D$2:$D$100,$C21,Teachers!$L$2:$L$100,"Active") -> 3 | H21: =SUMIFS(Teachers!$I$2:$I$100,Teachers!$E$2:$E$100,$A21,Teachers!$D$2:$D$100,$C21) -> 90 | I21: =SUMIFS(Teachers!$I$2:$I$100,Teachers!$E$2:$E$100,$A21,Teachers!$D$2:$D$100,$C21,Teachers!$L$2:$L$100,"Active") -> 90 | J21: =I21-E21 -> 55 | K21: =IF(I21=0,"n/a",E21/I21) -> 0.38888889 | L21: =IF(G21=0,"n/a",ROUND(J21/(I21/G21),1)) -> 1.8 | M21: =IF(I21=0,"NO TEACHER",IF(E21/I21>1,"SHORTAGE",IF(E21/I21>=$E$5,"TIGHT",IF(E21/I21>=$E$6,"BALANCED","SURPLUS")))) -> SURPLUS
A22: SCI | B22: Science | C22: PRT | D22: Class 1-5 | E22: =SUMIFS(Requirements!$G$2:$G$588,Requirements!$E$2:$E$588,$A22,Requirements!$J$2:$J$588,$C22) -> 48 | F22: =COUNTIFS(Teachers!$E$2:$E$100,$A22,Teachers!$D$2:$D$100,$C22) -> 2 | G22: =COUNTIFS(Teachers!$E$2:$E$100,$A22,Teachers!$D$2:$D$100,$C22,Teachers!$L$2:$L$100,"Active") -> 2 | H22: =SUMIFS(Teachers!$I$2:$I$100,Teachers!$E$2:$E$100,$A22,Teachers!$D$2:$D$100,$C22) -> 60 | I22: =SUMIFS(Teachers!$I$2:$I$100,Teachers!$E$2:$E$100,$A22,Teachers!$D$2:$D$100,$C22,Teachers!$L$2:$L$100,"Active") -> 60 | J22: =I22-E22 -> 12 | K22: =IF(I22=0,"n/a",E22/I22) -> 0.8 | L22: =IF(G22=0,"n/a",ROUND(J22/(I22/G22),1)) -> 0.4 | M22: =IF(I22=0,"NO TEACHER",IF(E22/I22>1,"SHORTAGE",IF(E22/I22>=$E$5,"TIGHT",IF(E22/I22>=$E$6,"BALANCED","SURPLUS")))) -> BALANCED
A23: SST | B23: Social Science | C23: PRT | D23: Class 1-5 | E23: =SUMIFS(Requirements!$G$2:$G$588,Requirements!$E$2:$E$588,$A23,Requirements!$J$2:$J$588,$C23) -> 48 | F23: =COUNTIFS(Teachers!$E$2:$E$100,$A23,Teachers!$D$2:$D$100,$C23) -> 3 | G23: =COUNTIFS(Teachers!$E$2:$E$100,$A23,Teachers!$D$2:$D$100,$C23,Teachers!$L$2:$L$100,"Active") -> 3 | H23: =SUMIFS(Teachers!$I$2:$I$100,Teachers!$E$2:$E$100,$A23,Teachers!$D$2:$D$100,$C23) -> 90 | I23: =SUMIFS(Teachers!$I$2:$I$100,Teachers!$E$2:$E$100,$A23,Teachers!$D$2:$D$100,$C23,Teachers!$L$2:$L$100,"Active") -> 90 | J23: =I23-E23 -> 42 | K23: =IF(I23=0,"n/a",E23/I23) -> 0.53333333 | L23: =IF(G23=0,"n/a",ROUND(J23/(I23/G23),1)) -> 1.4 | M23: =IF(I23=0,"NO TEACHER",IF(E23/I23>1,"SHORTAGE",IF(E23/I23>=$E$5,"TIGHT",IF(E23/I23>=$E$6,"BALANCED","SURPLUS")))) -> SURPLUS
A24: ENG | B24: English | C24: TGT | D24: Class 6-10 (Computer 1-10) | E24: =SUMIFS(Requirements!$G$2:$G$588,Requirements!$E$2:$E$588,$A24,Requirements!$J$2:$J$588,$C24) -> 141 | F24: =COUNTIFS(Teachers!$E$2:$E$100,$A24,Teachers!$D$2:$D$100,$C24) -> 5 | G24: =COUNTIFS(Teachers!$E$2:$E$100,$A24,Teachers!$D$2:$D$100,$C24,Teachers!$L$2:$L$100,"Active") -> 5 | H24: =SUMIFS(Teachers!$I$2:$I$100,Teachers!$E$2:$E$100,$A24,Teachers!$D$2:$D$100,$C24) -> 150 | I24: =SUMIFS(Teachers!$I$2:$I$100,Teachers!$E$2:$E$100,$A24,Teachers!$D$2:$D$100,$C24,Teachers!$L$2:$L$100,"Active") -> 150 | J24: =I24-E24 -> 9 | K24: =IF(I24=0,"n/a",E24/I24) -> 0.94 | L24: =IF(G24=0,"n/a",ROUND(J24/(I24/G24),1)) -> 0.3 | M24: =IF(I24=0,"NO TEACHER",IF(E24/I24>1,"SHORTAGE",IF(E24/I24>=$E$5,"TIGHT",IF(E24/I24>=$E$6,"BALANCED","SURPLUS")))) -> TIGHT
... A48: LIB | B48: Library & Reading | C48: Specialist | D48: All / per subject | E48: =SUMIFS(Requirements!$G$2:$G$588,Requirements!$E$2:$E$588,$A48,Requirements!$J$2:$J$588,$C48) -> 55 | F48: =COUNTIFS(Teachers!$E$2:$E$100,$A48,Teachers!$D$2:$D$100,$C48) -> 1 | G48: =COUNTIFS(Teachers!$E$2:$E$100,$A48,Teachers!$D$2:$D$100,$C48,Teachers!$L$2:$L$100,"Active") -> 1 | H48: =SUMIFS(Teachers!$I$2:$I$100,Teachers!$E$2:$E$100,$A48,Teachers!$D$2:$D$100,$C48) -> 30 | I48: =SUMIFS(Teachers!$I$2:$I$100,Teachers!$E$2:$E$100,$A48,Teachers!$D$2:$D$100,$C48,Teachers!$L$2:$L$100,"Active") -> 30 | J48: =I48-E48 -> -25 | K48: =IF(I48=0,"n/a",E48/I48) -> 1.8333333 | L48: =IF(G48=0,"n/a",ROUND(J48/(I48/G48),1)) -> -0.8 | M48: =IF(I48=0,"NO TEACHER",IF(E48/I48>1,"SHORTAGE",IF(E48/I48>=$E$5,"TIGHT",IF(E48/I48>=$E$6,"BALANCED","SURPLUS")))) -> SHORTAGE
A49: TOTAL | E49: =SUM(E13:E48) -> 2338 | F49: =SUM(F13:F48) -> 99 | G49: =SUM(G13:G48) -> 98 | H49: =SUM(H13:H48) -> 2816 | I49: =SUM(I13:I48) -> 2790 | J49: =SUM(J13:J48) -> 452

Sheet Room_Check
A1: Specialised room capacity check (live formulas)
A3: Weekly period slots per room | B3: 48 | C3: Assumption: 8 periods x 6 days. Only lessons with Room_Mandatory = Y are counted.
A5: Room_Type | B5: Rooms_Available | C5: Classes_At_Once | D5: Slot_Capacity_Week | E5: Periods_Needed_Week | F5: Utilization | G5: Status | H5: Note
A6: Computer Lab | B6: =COUNTIF(Rooms!$E$2:$E$68,A6) -> 2 | C6: =SUMIFS(Rooms!$G$2:$G$68,Rooms!$E$2:$E$68,A6) -> 2 | D6: =C6*$B$3 -> 96 | E6: =SUMIFS(Requirements!$G$2:$G$588,Requirements!$K$2:$K$588,A6,Requirements!$L$2:$L$588,"Y") -> 117 | F6: =IF(D6=0,"n/a",E6/D6) -> 1.21875 | G6: =IF(D6=0,"NO ROOM",IF(E6/D6>1,"SHORTAGE",IF(E6/D6>=0.9,"TIGHT","BALANCED"))) -> SHORTAGE | H6: All Computer Science / IT periods for Class 1-12
A7: Physics Lab | B7: =COUNTIF(Rooms!$E$2:$E$68,A7) -> 1 | C7: =SUMIFS(Rooms!$G$2:$G$68,Rooms!$E$2:$E$68,A7) -> 1 | D7: =C7*$B$3 -> 48 | E7: =SUMIFS(Requirements!$G$2:$G$588,Requirements!$K$2:$K$588,A7,Requirements!$L$2:$L$588,"Y") -> 45 | F7: =IF(D7=0,"n/a",E7/D7) -> 0.9375 | G7: =IF(D7=0,"NO ROOM",IF(E7/D7>1,"SHORTAGE",IF(E7/D7>=0.9,"TIGHT","BALANCED"))) -> TIGHT | H7: Senior Physics only
A8: Chemistry Lab | B8: =COUNTIF(Rooms!$E$2:$E$68,A8) -> 1 | C8: =SUMIFS(Rooms!$G$2:$G$68,Rooms!$E$2:$E$68,A8) -> 1 | D8: =C8*$B$3 -> 48 | E8: =SUMIFS(Requirements!$G$2:$G$588,Requirements!$K$2:$K$588,A8,Requirements!$L$2:$L$588,"Y") -> 45 | F8: =IF(D8=0,"n/a",E8/D8) -> 0.9375 | G8: =IF(D8=0,"NO ROOM",IF(E8/D8>1,"SHORTAGE",IF(E8/D8>=0.9,"TIGHT","BALANCED"))) -> TIGHT | H8: Senior Chemistry only
A9: Biology Lab | B9: =COUNTIF(Rooms!$E$2:$E$68,A9) -> 1 | C9: =SUMIFS(Rooms!$G$2:$G$68,Rooms!$E$2:$E$68,A9) -> 1 | D9: =C9*$B$3 -> 48 | E9: =SUMIFS(Requirements!$G$2:$G$588,Requirements!$K$2:$K$588,A9,Requirements!$L$2:$L$588,"Y") -> 20 | F9: =IF(D9=0,"n/a",E9/D9) -> 0.41666667 | G9: =IF(D9=0,"NO ROOM",IF(E9/D9>1,"SHORTAGE",IF(E9/D9>=0.9,"TIGHT","BALANCED"))) -> BALANCED | H9: Senior Biology (PCB) only
A10: Library | B10: =COUNTIF(Rooms!$E$2:$E$68,A10) -> 1 | C10: =SUMIFS(Rooms!$G$2:$G$68,Rooms!$E$2:$E$68,A10) -> 2 | D10: =C10*$B$3 -> 96 | E10: =SUMIFS(Requirements!$G$2:$G$588,Requirements!$K$2:$K$588,A10,Requirements!$L$2:$L$588,"Y") -> 55 | F10: =IF(D10=0,"n/a",E10/D10) -> 0.57291667 | G10: =IF(D10=0,"NO ROOM",IF(E10/D10>1,"SHORTAGE",IF(E10/D10>=0.9,"TIGHT","BALANCED"))) -> BALANCED | H10: Library periods for Class 1-12
A11: Playground | B11: =COUNTIF(Rooms!$E$2:$E$68,A11) -> 1 | C11: =SUMIFS(Rooms!$G$2:$G$68,Rooms!$E$2:$E$68,A11) -> 4 | D11: =C11*$B$3 -> 192 | E11: =SUMIFS(Requirements!$G$2:$G$588,Requirements!$K$2:$K$588,A11,Requirements!$L$2:$L$588,"Y") -> 180 | F11: =IF(D11=0,"n/a",E11/D11) -> 0.9375 | G11: =IF(D11=0,"NO ROOM",IF(E11/D11>1,"SHORTAGE",IF(E11/D11>=0.9,"TIGHT","BALANCED"))) -> TIGHT | H11: Physical Education Class 1-12
A12: Play Area | B12: =COUNTIF(Rooms!$E$2:$E$68,A12) -> 1 | C12: =SUMIFS(Rooms!$G$2:$G$68,Rooms!$E$2:$E$68,A12) -> 2 | D12: =C12*$B$3 -> 96 | E12: =SUMIFS(Requirements!$G$2:$G$588,Requirements!$K$2:$K$588,A12,Requirements!$L$2:$L$588,"Y") -> 21 | F12: =IF(D12=0,"n/a",E12/D12) -> 0.21875 | G12: =IF(D12=0,"NO ROOM",IF(E12/D12>1,"SHORTAGE",IF(E12/D12>=0.9,"TIGHT","BALANCED"))) -> BALANCED | H12: Pre-Primary Physical Activity
A13: Dance Studio | B13: =COUNTIF(Rooms!$E$2:$E$68,A13) -> 1 | C13: =SUMIFS(Rooms!$G$2:$G$68,Rooms!$E$2:$E$68,A13) -> 1 | D13: =C13*$B$3 -> 48 | E13: =SUMIFS(Requirements!$G$2:$G$588,Requirements!$K$2:$K$588,A13,Requirements!$L$2:$L$588,"Y") -> 30 | F13: =IF(D13=0,"n/a",E13/D13) -> 0.625 | G13: =IF(D13=0,"NO ROOM",IF(E13/D13>1,"SHORTAGE",IF(E13/D13>=0.9,"TIGHT","BALANCED"))) -> BALANCED | H13: Dance periods for Class 1-8

Sheet Known_Issues
A1: Issue_ID | B1: Type | C1: Severity | D1: Area | E1: What is wrong | F1: Numbers / evidence | G1: How the website should handle or test it
A2: ISS-01 | B2: Shortage | C2: High | D2: Physics (PGT) | E2: Only one Physics teacher (T001 Nidhi Tiwari) for 5 science sections in Class 11-12. | F2: Need 45 periods/week, capacity 26 (max load) -> short by 19 periods. | G2: Timetable generator should leave the overflow Physics periods unassigned and report exactly which sections are affected, not crash or silently drop them.
A3: ISS-02 | B3: Shortage (leave) | C3: High | D3: Mathematics (PGT) | E3: Two senior Maths teachers on roll, but T002 Madhu Sinha is on maternity leave until 31-Jan-2027. She is also the class teacher of 11-C. | F3: Need 51 periods/week. Nominal capacity 52 (looks fine), effective capacity 26 -> short by 25. | G3: Respect Teachers.Status / Status_Till. Show a 'needs substitute class teacher' warning for 11-C. Test that On Leave teachers get zero periods.
A4: ISS-03 | B4: Shortage (marginal) | C4: Medium | D4: Accountancy and Business Studies (PGT) | E4: One teacher each (T004 Pradeep Malhotra; T019 Rohit Jain) and the commerce sections need slightly more than a full load. | F4: Accountancy need 30 vs capacity 26; Business Studies need 27 vs capacity 26. | G4: Small gaps (4 and 1 periods) - checks that the app shows partial shortages, and that Economics teachers with BST/ACC as secondary subject can be suggested.
A5: ISS-04 | B5: Shortage | C5: High | D5: Sanskrit (TGT) | E5: One Sanskrit teacher (T011 Tarun Khanna) for 11 sections of Class 6-8. | F5: Need 44 periods/week, capacity 30 -> short by 14. | G5: Fix is possible from the Hindi surplus: 3 Hindi TGTs list Sanskrit as Secondary_Subject (T009 Radha Bansal, T028 Poonam Thakur, T044 Pallavi Walia). Good test for 'suggest from secondary subject' logic.
A6: ISS-05 | B6: Shortage | C6: High | D6: Computer (Class 1-10) | E6: Only 2 full-time and 1 part-time computer teacher (T022 Renu Banerjee, Mon/Wed/Fri only) for 38 sections of Class 1-10. | F6: Need 96 periods/week, capacity 75 -> short by 21. | G6: Teachers with CS as secondary subject: T025 Bhavna Gill, T029 Vinod Ghosh, T030 Rajesh Kumar, T076 Pankaj Reddy.
A7: ISS-06 | B7: Shortage | C7: Medium | D7: Music | E7: One full-time music teacher plus one part-time (T092 Renu Joshi, Tue/Thu only). | F7: Need 51 periods/week, capacity 40 -> short by 11. | G7: The visiting dance teacher (T067 Varsha Sinha) lists Music as a secondary subject and could cover part of the gap.
A8: ISS-07 | B8: Shortage | C8: High | D8: Dance | E8: Dance is taught by a visiting teacher (T067 Varsha Sinha) available Mon/Wed/Fri only, max 12 periods a week. | F8: Need 30 periods/week, capacity 12 -> short by 18. | G8: Some Class 1-8 sections will not get all their Dance periods. The full-time music teacher lists Dance as a secondary subject.
A9: ISS-08 | B9: Shortage | C9: Medium | D9: Library | E9: One librarian (T050 Renu Tandon) for library periods of all 48 sections of Class 1-12. | F9: Need 55 periods/week, capacity 30 -> short by 25. | G9: Tests handling of a single-teacher subject that spans every wing.
A10: ISS-09 | B10: Surplus | C10: Medium | D10: EVS (Primary) | E10: 3 teachers for a small workload. EVS exists only in Class 1-2, but 3 PRTs are hired for it. | F10: Need 35 periods/week, capacity 90 -> utilization 39% (about 1.8 teachers spare). | G10: App should show these as under-used and avoid forcing full loads. Spare teachers can cover shortage subjects via their secondary subjects.
A11: ISS-10 | B11: Surplus | C11: Low | D11: Social Science (Primary) | E11: 3 teachers for a small workload. Only Class 3-5 teach it (12 sections x 4 periods). | F11: Need 48 periods/week, capacity 90 -> utilization 53% (about 1.4 teachers spare). | G11: App should show these as under-used and avoid forcing full loads. Spare teachers can cover shortage subjects via their secondary subjects.
A12: ISS-11 | B12: Surplus | C12: Low | D12: Hindi (Class 6-10) | E12: 7 teachers for a small workload. Seven TGTs for the Hindi periods of 19 sections; three of them also list Sanskrit as a secondary subject. | F12: Need 114 periods/week, capacity 210 -> utilization 54% (about 3.2 teachers spare). | G12: App should show these as under-used and avoid forcing full loads. Spare teachers can cover shortage subjects via their secondary subjects.
... A24: ISS-23 | B24: Constraint | C24: Low | D24: Class teacher period | E24: Value Education / Circle Time must always be taken by the section's own class teacher (all 55 sections have one). | F24: Class teacher of 11-C (T002 Madhu Sinha) is on leave - see ISS-02. | G24: Place the class-teacher period in a slot when that teacher is free; supply a substitute when the class teacher is unavailable.
